Traceback (most recent call last):
  File "/usr/local/lib/python3.5/dist-packages/gunicorn/arbiter.py", line 224, in run
    handler()
  File "/usr/local/lib/python3.5/dist-packages/gunicorn/arbiter.py", line 259, in handle_term
    raise StopIteration
StopIteration

During handling of the above exception, another exception occurred:

Traceback (most recent call last):
  File "/usr/local/bin/gunicorn", line 11, in <module>
    sys.exit(run())
  File "/usr/local/lib/python3.5/dist-packages/gunicorn/app/wsgiapp.py", line 74, in run
    WSGIApplication("%(prog)s [OPTIONS] [APP_MODULE]").run()
  File "/usr/local/lib/python3.5/dist-packages/gunicorn/app/base.py", line 203, in run
    super(Application, self).run()
  File "/usr/local/lib/python3.5/dist-packages/gunicorn/app/base.py", line 72, in run
    Arbiter(self).run()
  File "/usr/local/lib/python3.5/dist-packages/gunicorn/arbiter.py", line 227, in run
    self.halt()
  File "/usr/local/lib/python3.5/dist-packages/gunicorn/arbiter.py", line 344, in halt
    self.stop()
  File "/usr/local/lib/python3.5/dist-packages/gunicorn/arbiter.py", line 382, in stop
    sock.close_sockets(self.LISTENERS, unlink)
  File "/usr/local/lib/python3.5/dist-packages/gunicorn/sock.py", line 208, in close_sockets
    os.unlink(sock_name)
FileNotFoundError: [Errno 2] No such file or directory: '/home/krodik/www/elostat/elostat/run/unicorn.sock'
Not Found: /favicon.ico
Not Found: /
Not Found: /favicon.ico
Not Found: /outcomes
Not Found: /elostat.png
Not Found: /baseball.png
Internal Server Error: /outcomes/20171010
Traceback (most recent call last):
  File "/usr/local/lib/python3.5/dist-packages/django/core/handlers/exception.py", line 41, in inner
    response = get_response(request)
  File "/usr/local/lib/python3.5/dist-packages/django/core/handlers/base.py", line 187, in _get_response
    response = self.process_exception_by_middleware(e, request)
  File "/usr/local/lib/python3.5/dist-packages/django/core/handlers/base.py", line 185, in _get_response
    response = wrapped_callback(request, *callback_args, **callback_kwargs)
  File "/home/krodik/www/elostat/outcomes/views.py", line 22, in homepage
    return HttpResponse(template.render(context, request))
UnboundLocalError: local variable 'template' referenced before assignment
Not Found: /
Internal Server Error: /outcomes/20171010
Traceback (most recent call last):
  File "/usr/local/lib/python3.5/dist-packages/django/core/handlers/exception.py", line 41, in inner
    response = get_response(request)
  File "/usr/local/lib/python3.5/dist-packages/django/core/handlers/base.py", line 187, in _get_response
    response = self.process_exception_by_middleware(e, request)
  File "/usr/local/lib/python3.5/dist-packages/django/core/handlers/base.py", line 185, in _get_response
    response = wrapped_callback(request, *callback_args, **callback_kwargs)
  File "/home/krodik/www/elostat/outcomes/views.py", line 22, in homepage
    return HttpResponse(template.render(context, request))
UnboundLocalError: local variable 'template' referenced before assignment
Not Found: /
Internal Server Error: /outcomes/20171010
Traceback (most recent call last):
  File "/usr/local/lib/python3.5/dist-packages/django/core/handlers/exception.py", line 41, in inner
    response = get_response(request)
  File "/usr/local/lib/python3.5/dist-packages/django/core/handlers/base.py", line 187, in _get_response
    response = self.process_exception_by_middleware(e, request)
  File "/usr/local/lib/python3.5/dist-packages/django/core/handlers/base.py", line 185, in _get_response
    response = wrapped_callback(request, *callback_args, **callback_kwargs)
  File "/home/krodik/www/elostat/outcomes/views.py", line 22, in homepage
    return HttpResponse(template.render(context, request))
UnboundLocalError: local variable 'template' referenced before assignment
Not Found: /outcomes
Not Found: /
Not Found: /outcomes
Not Found: /outcomes
Not Found: /outcomes
Not Found: /outcomes
Not Found: /outcomes
Internal Server Error: /outcomes
Traceback (most recent call last):
  File "/usr/local/lib/python3.5/dist-packages/django/core/handlers/exception.py", line 41, in inner
    response = get_response(request)
  File "/usr/local/lib/python3.5/dist-packages/django/utils/deprecation.py", line 138, in __call__
    response = self.process_request(request)
  File "/usr/local/lib/python3.5/dist-packages/django/middleware/common.py", line 62, in process_request
    if self.should_redirect_with_slash(request):
  File "/usr/local/lib/python3.5/dist-packages/django/middleware/common.py", line 80, in should_redirect_with_slash
    not is_valid_path(request.path_info, urlconf) and
  File "/usr/local/lib/python3.5/dist-packages/django/urls/base.py", line 158, in is_valid_path
    resolve(path, urlconf)
  File "/usr/local/lib/python3.5/dist-packages/django/urls/base.py", line 27, in resolve
    return get_resolver(urlconf).resolve(path)
  File "/usr/local/lib/python3.5/dist-packages/django/urls/resolvers.py", line 362, in resolve
    for pattern in self.url_patterns:
  File "/usr/local/lib/python3.5/dist-packages/django/utils/functional.py", line 35, in __get__
    res = instance.__dict__[self.name] = self.func(instance)
  File "/usr/local/lib/python3.5/dist-packages/django/urls/resolvers.py", line 405, in url_patterns
    patterns = getattr(self.urlconf_module, "urlpatterns", self.urlconf_module)
  File "/usr/local/lib/python3.5/dist-packages/django/utils/functional.py", line 35, in __get__
    res = instance.__dict__[self.name] = self.func(instance)
  File "/usr/local/lib/python3.5/dist-packages/django/urls/resolvers.py", line 398, in urlconf_module
    return import_module(self.urlconf_name)
  File "/usr/lib/python3.5/importlib/__init__.py", line 126, in import_module
    return _bootstrap._gcd_import(name[level:], package, level)
  File "<frozen importlib._bootstrap>", line 986, in _gcd_import
  File "<frozen importlib._bootstrap>", line 969, in _find_and_load
  File "<frozen importlib._bootstrap>", line 958, in _find_and_load_unlocked
  File "<frozen importlib._bootstrap>", line 673, in _load_unlocked
  File "<frozen importlib._bootstrap_external>", line 665, in exec_module
  File "<frozen importlib._bootstrap>", line 222, in _call_with_frames_removed
  File "/home/krodik/www/elostat/elostat/urls.py", line 18, in <module>
    from outcomes import views
  File "/home/krodik/www/elostat/outcomes/views.py", line 27
    d = datetime.date(2017,10,01)
                               ^
SyntaxError: invalid token
Internal Server Error: /outcomes
Traceback (most recent call last):
  File "/usr/local/lib/python3.5/dist-packages/django/core/handlers/exception.py", line 41, in inner
    response = get_response(request)
  File "/usr/local/lib/python3.5/dist-packages/django/core/handlers/base.py", line 187, in _get_response
    response = self.process_exception_by_middleware(e, request)
  File "/usr/local/lib/python3.5/dist-packages/django/core/handlers/base.py", line 185, in _get_response
    response = wrapped_callback(request, *callback_args, **callback_kwargs)
  File "/home/krodik/www/elostat/outcomes/views.py", line 30, in homepage
    if(all_games[i].date > d):
NameError: name 'i' is not defined
Internal Server Error: /outcomes
Traceback (most recent call last):
  File "/usr/local/lib/python3.5/dist-packages/django/core/handlers/exception.py", line 41, in inner
    response = get_response(request)
  File "/usr/local/lib/python3.5/dist-packages/django/core/handlers/base.py", line 187, in _get_response
    response = self.process_exception_by_middleware(e, request)
  File "/usr/local/lib/python3.5/dist-packages/django/core/handlers/base.py", line 185, in _get_response
    response = wrapped_callback(request, *callback_args, **callback_kwargs)
  File "/home/krodik/www/elostat/outcomes/views.py", line 30, in homepage
    if(all_games[g].date > d):
NameError: name 'i' is not defined
Internal Server Error: /outcomes/Oct. 4, 2017
Traceback (most recent call last):
  File "/usr/local/lib/python3.5/dist-packages/django/core/handlers/exception.py", line 41, in inner
    response = get_response(request)
  File "/usr/local/lib/python3.5/dist-packages/django/core/handlers/base.py", line 187, in _get_response
    response = self.process_exception_by_middleware(e, request)
  File "/usr/local/lib/python3.5/dist-packages/django/core/handlers/base.py", line 185, in _get_response
    response = wrapped_callback(request, *callback_args, **callback_kwargs)
  File "/home/krodik/www/elostat/outcomes/views.py", line 30, in homepage
    if(all_games[g].date > d):
NameError: name 'i' is not defined
Internal Server Error: /outcomes
Traceback (most recent call last):
  File "/usr/local/lib/python3.5/dist-packages/django/core/handlers/exception.py", line 41, in inner
    response = get_response(request)
  File "/usr/local/lib/python3.5/dist-packages/django/core/handlers/base.py", line 187, in _get_response
    response = self.process_exception_by_middleware(e, request)
  File "/usr/local/lib/python3.5/dist-packages/django/core/handlers/base.py", line 185, in _get_response
    response = wrapped_callback(request, *callback_args, **callback_kwargs)
  File "/home/krodik/www/elostat/outcomes/views.py", line 30, in homepage
    if(all_games[g].date > d):
NameError: name 'i' is not defined
Not Found: /elostat.png
Internal Server Error: /outcomes
Traceback (most recent call last):
  File "/usr/local/lib/python3.5/dist-packages/django/core/handlers/exception.py", line 41, in inner
    response = get_response(request)
  File "/usr/local/lib/python3.5/dist-packages/django/core/handlers/base.py", line 187, in _get_response
    response = self.process_exception_by_middleware(e, request)
  File "/usr/local/lib/python3.5/dist-packages/django/core/handlers/base.py", line 185, in _get_response
    response = wrapped_callback(request, *callback_args, **callback_kwargs)
  File "/home/krodik/www/elostat/outcomes/views.py", line 30, in homepage
    if(all_games[g].date > d):
NameError: name 'i' is not defined
Internal Server Error: /outcomes
Traceback (most recent call last):
  File "/usr/local/lib/python3.5/dist-packages/django/core/handlers/exception.py", line 41, in inner
    response = get_response(request)
  File "/usr/local/lib/python3.5/dist-packages/django/core/handlers/base.py", line 187, in _get_response
    response = self.process_exception_by_middleware(e, request)
  File "/usr/local/lib/python3.5/dist-packages/django/core/handlers/base.py", line 185, in _get_response
    response = wrapped_callback(request, *callback_args, **callback_kwargs)
  File "/home/krodik/www/elostat/outcomes/views.py", line 30, in homepage
    if(all_games[g].date > d):
NameError: name 'i' is not defined
Internal Server Error: /outcomes
Traceback (most recent call last):
  File "/usr/local/lib/python3.5/dist-packages/django/core/handlers/exception.py", line 41, in inner
    response = get_response(request)
  File "/usr/local/lib/python3.5/dist-packages/django/core/handlers/base.py", line 187, in _get_response
    response = self.process_exception_by_middleware(e, request)
  File "/usr/local/lib/python3.5/dist-packages/django/core/handlers/base.py", line 185, in _get_response
    response = wrapped_callback(request, *callback_args, **callback_kwargs)
  File "/home/krodik/www/elostat/outcomes/views.py", line 30, in homepage
    if(all_games[g].date > d):
NameError: name 'i' is not defined
Not Found: /elostat.png
Not Found: /baseball.png
Not Found: /elostat.png
Internal Server Error: /outcomes/20171009
Traceback (most recent call last):
  File "/usr/local/lib/python3.5/dist-packages/django/core/handlers/exception.py", line 41, in inner
    response = get_response(request)
  File "/usr/local/lib/python3.5/dist-packages/django/core/handlers/base.py", line 187, in _get_response
    response = self.process_exception_by_middleware(e, request)
  File "/usr/local/lib/python3.5/dist-packages/django/core/handlers/base.py", line 185, in _get_response
    response = wrapped_callback(request, *callback_args, **callback_kwargs)
  File "/home/krodik/www/elostat/outcomes/views.py", line 30, in homepage
    if(all_games[g].date > d):
NameError: name 'i' is not defined
Not Found: /elostat.png
Internal Server Error: /outcomes/
Traceback (most recent call last):
  File "/usr/local/lib/python3.5/dist-packages/django/core/handlers/exception.py", line 41, in inner
    response = get_response(request)
  File "/usr/local/lib/python3.5/dist-packages/django/core/handlers/base.py", line 187, in _get_response
    response = self.process_exception_by_middleware(e, request)
  File "/usr/local/lib/python3.5/dist-packages/django/core/handlers/base.py", line 185, in _get_response
    response = wrapped_callback(request, *callback_args, **callback_kwargs)
  File "/home/krodik/www/elostat/outcomes/views.py", line 30, in homepage
    if(all_games[g].date > d):
NameError: name 'i' is not defined
Not Found: /elostat.png
Not Found: /media/elostat.png
Internal Server Error: /outcomes/
Traceback (most recent call last):
  File "/usr/local/lib/python3.5/dist-packages/django/template/base.py", line 507, in parse
    compile_func = self.tags[command]
KeyError: 'static'

During handling of the above exception, another exception occurred:

Traceback (most recent call last):
  File "/usr/local/lib/python3.5/dist-packages/django/core/handlers/exception.py", line 41, in inner
    response = get_response(request)
  File "/usr/local/lib/python3.5/dist-packages/django/core/handlers/base.py", line 187, in _get_response
    response = self.process_exception_by_middleware(e, request)
  File "/usr/local/lib/python3.5/dist-packages/django/core/handlers/base.py", line 185, in _get_response
    response = wrapped_callback(request, *callback_args, **callback_kwargs)
  File "/home/krodik/www/elostat/outcomes/views.py", line 32, in homepage
    template = loader.get_template('outcomes/latest.html')
  File "/usr/local/lib/python3.5/dist-packages/django/template/loader.py", line 21, in get_template
    return engine.get_template(template_name)
  File "/usr/local/lib/python3.5/dist-packages/django/template/backends/django.py", line 39, in get_template
    return Template(self.engine.get_template(template_name), self)
  File "/usr/local/lib/python3.5/dist-packages/django/template/engine.py", line 162, in get_template
    template, origin = self.find_template(template_name)
  File "/usr/local/lib/python3.5/dist-packages/django/template/engine.py", line 136, in find_template
    name, template_dirs=dirs, skip=skip,
  File "/usr/local/lib/python3.5/dist-packages/django/template/loaders/base.py", line 44, in get_template
    contents, origin, origin.template_name, self.engine,
  File "/usr/local/lib/python3.5/dist-packages/django/template/base.py", line 191, in __init__
    self.nodelist = self.compile_nodelist()
  File "/usr/local/lib/python3.5/dist-packages/django/template/base.py", line 230, in compile_nodelist
    return parser.parse()
  File "/usr/local/lib/python3.5/dist-packages/django/template/base.py", line 509, in parse
    self.invalid_block_tag(token, command, parse_until)
  File "/usr/local/lib/python3.5/dist-packages/django/template/base.py", line 571, in invalid_block_tag
    "or load this tag?" % (token.lineno, command)
django.template.exceptions.TemplateSyntaxError: Invalid block tag on line 59: 'static'. Did you forget to register or load this tag?
Internal Server Error: /outcomes/
Traceback (most recent call last):
  File "/usr/local/lib/python3.5/dist-packages/django/template/base.py", line 507, in parse
    compile_func = self.tags[command]
KeyError: 'static'

During handling of the above exception, another exception occurred:

Traceback (most recent call last):
  File "/usr/local/lib/python3.5/dist-packages/django/core/handlers/exception.py", line 41, in inner
    response = get_response(request)
  File "/usr/local/lib/python3.5/dist-packages/django/core/handlers/base.py", line 187, in _get_response
    response = self.process_exception_by_middleware(e, request)
  File "/usr/local/lib/python3.5/dist-packages/django/core/handlers/base.py", line 185, in _get_response
    response = wrapped_callback(request, *callback_args, **callback_kwargs)
  File "/home/krodik/www/elostat/outcomes/views.py", line 32, in homepage
    template = loader.get_template('outcomes/latest.html')
  File "/usr/local/lib/python3.5/dist-packages/django/template/loader.py", line 21, in get_template
    return engine.get_template(template_name)
  File "/usr/local/lib/python3.5/dist-packages/django/template/backends/django.py", line 39, in get_template
    return Template(self.engine.get_template(template_name), self)
  File "/usr/local/lib/python3.5/dist-packages/django/template/engine.py", line 162, in get_template
    template, origin = self.find_template(template_name)
  File "/usr/local/lib/python3.5/dist-packages/django/template/engine.py", line 136, in find_template
    name, template_dirs=dirs, skip=skip,
  File "/usr/local/lib/python3.5/dist-packages/django/template/loaders/base.py", line 44, in get_template
    contents, origin, origin.template_name, self.engine,
  File "/usr/local/lib/python3.5/dist-packages/django/template/base.py", line 191, in __init__
    self.nodelist = self.compile_nodelist()
  File "/usr/local/lib/python3.5/dist-packages/django/template/base.py", line 230, in compile_nodelist
    return parser.parse()
  File "/usr/local/lib/python3.5/dist-packages/django/template/base.py", line 509, in parse
    self.invalid_block_tag(token, command, parse_until)
  File "/usr/local/lib/python3.5/dist-packages/django/template/base.py", line 571, in invalid_block_tag
    "or load this tag?" % (token.lineno, command)
django.template.exceptions.TemplateSyntaxError: Invalid block tag on line 59: 'static'. Did you forget to register or load this tag?
Not Found: /media/elostat.png
Not Found: /media/elostat.png
Not Found: /media/elostat.png
Not Found: /media/elostat.png
Not Found: /outcomes/20171004
Not Found: /elostat.png
Not Found: /baseball.png
Not Found: /outcomes
Not Found: /outcomes
Not Found: /outcomes
Not Found: /media/elostat.png
Not Found: /
Not Found: /
Not Found: /elostat.png
Not Found: /baseball.png
Not Found: /favicon.ico
Not Found: /media/
Not Found: /media/elostat.png
